<?xml version="1.0" ?>
<!-- =================================================================================== -->
<!-- |    This document was autogenerated by xacro from model.urdf.xacro               | -->
<!-- |    EDITING THIS FILE BY HAND IS NOT RECOMMENDED                                 | -->
<!-- =================================================================================== -->
<robot name="triple_pendulum">
  <!-- ======================================== -->
  <!-- Reference coordinate system              -->
  <!-- ======================================== -->
  <link name="world"/>
  <!-- ======================================== -->
  <!-- Definitions of materials                 -->
  <!-- ======================================== -->
  <material name="black">
    <color rgba="0.0 0.0 0.0 1.0"/>
  </material>
  <material name="white">
    <color rgba="1.0 1.0 1.0 1.0"/>
  </material>
  <material name="gray">
    <color rgba="0.2 0.2 0.2 1.0"/>
  </material>
  <material name="blue">
    <color rgba="0.0 0.0 1.0 1.0"/>
  </material>
  <material name="green">
    <color rgba="0.0 0.6 0.0 1.0"/>
  </material>
  <material name="red">
    <color rgba="1.0 0.0 0.0 1.0"/>
  </material>
  <!-- ======================================== -->
  <!-- Linkages                                 -->
  <!-- ======================================== -->
  <!-- base_link -->
  <link name="base_link">
    <visual>
      <origin rpy="0.0 0.0 0.0" xyz="0.0 0.0 0.0"/>
      <geometry>
        <box size="1.4 0.01 0.01"/>
      </geometry>
      <material name="black"/>
    </visual>
    <!-- dummy -->
    <inertial>
      <origin rpy="0.0 0.0 0.0" xyz="0.0 0.0 0.0"/>
      <mass value="1.0"/>
      <inertia ixx="0.01" ixy="0.0" ixz="0.0" iyy="0.01" iyz="0.0" izz="0.01"/>
    </inertial>
  </link>
  <!-- cart -->
  <link name="cart">
    <visual>
      <origin rpy="0.0 0.0 0.0" xyz="0.0 0.0 0.0"/>
      <geometry>
        <box size="0.2 0.1 0.1"/>
      </geometry>
      <material name="gray"/>
    </visual>
    <inertial>
      <origin rpy="0.0 0.0 0.0" xyz="0.0 0.0 0.0"/>
      <mass value="1.0"/>
      <inertia ixx="0.01" ixy="0.0" ixz="0.0" iyy="0.01" iyz="0.0" izz="0.01"/>
    </inertial>
  </link>
  <!-- pendulum 1 -->
  <link name="pendulum1">
    <visual>
      <origin rpy="0.0 0.0 0.0" xyz="0.0 0.0 0.1615"/>
      <geometry>
        <box size="0.05 0.05 0.323"/>
      </geometry>
      <material name="blue"/>
    </visual>
    <inertial>
      <origin rpy="0.0 0.0 0.0" xyz="0.0 0.0 0.215"/>
      <mass value="0.876"/>
      <inertia ixx="0.013" ixy="0.0" ixz="0.0" iyy="0.013" iyz="0.0" izz="0.001"/>
    </inertial>
  </link>
  <!-- pendulum 2 -->
  <link name="pendulum2">
    <visual>
      <origin rpy="0.0 0.0 0.0" xyz="0.0 0.0 0.2095"/>
      <geometry>
        <box size="0.05 0.05 0.419"/>
      </geometry>
      <material name="green"/>
    </visual>
    <inertial>
      <origin rpy="0.0 0.0 0.0" xyz="0.0 0.0 0.269"/>
      <mass value="0.938"/>
      <inertia ixx="0.024" ixy="0.0" ixz="0.0" iyy="0.024" iyz="0.0" izz="0.001"/>
    </inertial>
  </link>
  <!-- pendulum 3 -->
  <link name="pendulum3">
    <visual>
      <origin rpy="0.0 0.0 0.0" xyz="0.0 0.0 0.242"/>
      <geometry>
        <box size="0.05 0.05 0.484"/>
      </geometry>
      <material name="red"/>
    </visual>
    <inertial>
      <origin rpy="0.0 0.0 0.0" xyz="0.0 0.0 0.226"/>
      <mass value="0.553"/>
      <inertia ixx="0.018" ixy="0.0" ixz="0.0" iyy="0.018" iyz="0.0" izz="0.001"/>
    </inertial>
  </link>
  <!-- ======================================== -->
  <!-- Joints                                   -->
  <!-- ======================================== -->
  <!-- base_joint (parent -> base_link) -->
  <joint name="base_joint" type="fixed">
    <parent link="world"/>
    <child link="base_link"/>
    <origin rpy="0.0 0.0 0.0" xyz="0.0 0.0 1.5"/>
  </joint>
  <!-- slider (base_link -> cart) -->
  <joint name="slider" type="prismatic">
    <parent link="base_link"/>
    <child link="cart"/>
    <origin rpy="0.0 0.0 0.0" xyz="0.0 0.0 0.0"/>
    <axis xyz="1.0 0.0 0.0"/>
    <limit effort="22.0" lower="-0.7" upper="0.7" velocity="3.0"/>
  </joint>
  <!-- joint1 (cart -> pendulum1) -->
  <joint name="joint1" type="continuous">
    <parent link="cart"/>
    <child link="pendulum1"/>
    <origin rpy="0.0 0.0 0.0" xyz="0.0 0.0 0.0"/>
    <axis xyz="0.0 1.0 0.0"/>
    <dynamics damping="0.215" friction="0.0"/>
  </joint>
  <!-- joint2 (pendulum1 -> pendulum2) -->
  <joint name="joint2" type="continuous">
    <parent link="pendulum1"/>
    <child link="pendulum2"/>
    <origin rpy="0.0 0.0 0.0" xyz="0.0 0.0 0.323"/>
    <axis xyz="0.0 1.0 0.0"/>
    <dynamics damping="0.002" friction="0.0"/>
  </joint>
  <!-- joint3 (pendulum2 -> pendulum3) -->
  <joint name="joint3" type="continuous">
    <parent link="pendulum2"/>
    <child link="pendulum3"/>
    <origin rpy="0.0 0.0 0.0" xyz="0.0 0.0 0.419"/>
    <axis xyz="0.0 1.0 0.0"/>
    <dynamics damping="0.002" friction="0.0"/>
  </joint>
  <!-- ======================================== -->
  <!-- ros2_control                             -->
  <!-- ======================================== -->
  <ros2_control name="triple_pendulum" type="system">
    <!-- ======================================== -->
    <!-- Hardwares                                -->
    <!-- ======================================== -->
    <hardware>
    </hardware>
    <!-- ======================================== -->
    <!-- Joints                                   -->
    <!-- ======================================== -->
    <!-- slider (base_link -> cart) -->
    <joint name="slider">
      <!-- input -->
      <command_interface name="position"/>
      <command_interface name="velocity"/>
      <command_interface name="effort"/>
      <!-- output -->
      <state_interface name="position">
        <param name="initial_value">0.0</param>
      </state_interface>
      <state_interface name="velocity">
        <param name="initial_value">0.0</param>
      </state_interface>
      <state_interface name="effort">
        <param name="initial_value">0.0</param>
      </state_interface>
    </joint>
    <!-- joint1 (cart -> pendulum1) -->
    <joint name="joint1">
      <!-- output -->
      <state_interface name="position">
        <param name="initial_value">0.0</param>
      </state_interface>
      <state_interface name="velocity">
        <param name="initial_value">0.0</param>
      </state_interface>
    </joint>
    <!-- joint2 (pendulum1 -> pendulum2) -->
    <joint name="joint2">
      <!-- output -->
      <state_interface name="position">
        <param name="initial_value">0.0</param>
      </state_interface>
      <state_interface name="velocity">
        <param name="initial_value">0.0</param>
      </state_interface>
    </joint>
    <!-- joint3 (pendulum2 -> pendulum3) -->
    <joint name="joint3">
      <!-- output -->
      <state_interface name="position">
        <param name="initial_value">0.0</param>
      </state_interface>
      <state_interface name="velocity">
        <param name="initial_value">0.0</param>
      </state_interface>
    </joint>
  </ros2_control>
</robot>
